[2022-01-10T19:17:58Z] DEBUG    - Logging set up successfully
[2022-01-10T19:17:58Z] DEBUG    - Running test: Namespace(version=False, subparser_name='test', command=<function test at 0x11f02e4d0>, verbose=0, endpoint='http://127.0.0.1:3001', function_name='TypeFunction', region='us-east-1', role_arn=None, cloudformation_endpoint_url=None, enforce_timeout='30', log_group_name=None, log_role_arn=None, passed_to_pytest=[], docker_image=None)
[2022-01-10T19:17:58Z] DEBUG    - Root directory: /Volumes/workplace/NM-CFN/src/AWSCloudFormationResourceProvidersNetworkManager
[2022-01-10T19:17:58Z] DEBUG    - Loading project file '/Volumes/workplace/NM-CFN/src/AWSCloudFormationResourceProvidersNetworkManager/.rpdk-config'
[2022-01-10T19:17:58Z] DEBUG    - Project file /Volumes/workplace/NM-CFN/src/AWSCloudFormationResourceProvidersNetworkManager/.rpdk-config not found. Have you run 'init' or in a wrong directory?
Traceback (most recent call last):
  File "/usr/local/Cellar/cloudformation-cli/0.2.22/libexec/lib/python3.10/site-packages/rpdk/core/project.py", line 442, in load
    self.load_settings()
  File "/usr/local/Cellar/cloudformation-cli/0.2.22/libexec/lib/python3.10/site-packages/rpdk/core/project.py", line 195, in load_settings
    with self.settings_path.open("r", encoding="utf-8") as f:
  File "/usr/local/Cellar/python@3.10/3.10.1/Frameworks/Python.framework/Versions/3.10/lib/python3.10/pathlib.py", line 1117, in open
    return self._accessor.open(self, mode, buffering, encoding, errors,
FileNotFoundError: [Errno 2] No such file or directory: '/Volumes/workplace/NM-CFN/src/AWSCloudFormationResourceProvidersNetworkManager/.rpdk-config'
[2022-01-10T19:17:58Z] DEBUG    - Caught exit recommendation
Traceback (most recent call last):
  File "/usr/local/Cellar/cloudformation-cli/0.2.22/libexec/lib/python3.10/site-packages/rpdk/core/project.py", line 442, in load
    self.load_settings()
  File "/usr/local/Cellar/cloudformation-cli/0.2.22/libexec/lib/python3.10/site-packages/rpdk/core/project.py", line 195, in load_settings
    with self.settings_path.open("r", encoding="utf-8") as f:
  File "/usr/local/Cellar/python@3.10/3.10.1/Frameworks/Python.framework/Versions/3.10/lib/python3.10/pathlib.py", line 1117, in open
    return self._accessor.open(self, mode, buffering, encoding, errors,
FileNotFoundError: [Errno 2] No such file or directory: '/Volumes/workplace/NM-CFN/src/AWSCloudFormationResourceProvidersNetworkManager/.rpdk-config'

The above exception was the direct cause of the following exception:

Traceback (most recent call last):
  File "/usr/local/Cellar/cloudformation-cli/0.2.22/libexec/lib/python3.10/site-packages/rpdk/core/cli.py", line 100, in main
    args.command(args)
  File "/usr/local/Cellar/cloudformation-cli/0.2.22/libexec/lib/python3.10/site-packages/rpdk/core/test.py", line 181, in test
    project.load()
  File "/usr/local/Cellar/cloudformation-cli/0.2.22/libexec/lib/python3.10/site-packages/rpdk/core/project.py", line 444, in load
    self._raise_invalid_project(
  File "/usr/local/Cellar/cloudformation-cli/0.2.22/libexec/lib/python3.10/site-packages/rpdk/core/project.py", line 190, in _raise_invalid_project
    raise InvalidProjectError(msg) from e
rpdk.core.exceptions.InvalidProjectError: Project file /Volumes/workplace/NM-CFN/src/AWSCloudFormationResourceProvidersNetworkManager/.rpdk-config not found. Have you run 'init' or in a wrong directory?
[2022-01-10T19:17:58Z] CRITICAL - Project file /Volumes/workplace/NM-CFN/src/AWSCloudFormationResourceProvidersNetworkManager/.rpdk-config not found. Have you run 'init' or in a wrong directory?
[2022-01-11T06:39:33Z] DEBUG    - Logging set up successfully
[2022-01-11T06:39:33Z] DEBUG    - Running validate: Namespace(version=False, subparser_name='validate', command=<function validate at 0x11f04a9e0>, verbose=0)
[2022-01-11T06:39:33Z] DEBUG    - Root directory: /Volumes/workplace/NM-CFN/src/AWSCloudFormationResourceProvidersNetworkManager
[2022-01-11T06:39:33Z] DEBUG    - Loading project file '/Volumes/workplace/NM-CFN/src/AWSCloudFormationResourceProvidersNetworkManager/.rpdk-config'
[2022-01-11T06:39:33Z] DEBUG    - Project file /Volumes/workplace/NM-CFN/src/AWSCloudFormationResourceProvidersNetworkManager/.rpdk-config not found. Have you run 'init' or in a wrong directory?
Traceback (most recent call last):
  File "/usr/local/Cellar/cloudformation-cli/0.2.22/libexec/lib/python3.10/site-packages/rpdk/core/project.py", line 442, in load
    self.load_settings()
  File "/usr/local/Cellar/cloudformation-cli/0.2.22/libexec/lib/python3.10/site-packages/rpdk/core/project.py", line 195, in load_settings
    with self.settings_path.open("r", encoding="utf-8") as f:
  File "/usr/local/Cellar/python@3.10/3.10.1/Frameworks/Python.framework/Versions/3.10/lib/python3.10/pathlib.py", line 1117, in open
    return self._accessor.open(self, mode, buffering, encoding, errors,
FileNotFoundError: [Errno 2] No such file or directory: '/Volumes/workplace/NM-CFN/src/AWSCloudFormationResourceProvidersNetworkManager/.rpdk-config'
[2022-01-11T06:39:33Z] DEBUG    - Caught exit recommendation
Traceback (most recent call last):
  File "/usr/local/Cellar/cloudformation-cli/0.2.22/libexec/lib/python3.10/site-packages/rpdk/core/project.py", line 442, in load
    self.load_settings()
  File "/usr/local/Cellar/cloudformation-cli/0.2.22/libexec/lib/python3.10/site-packages/rpdk/core/project.py", line 195, in load_settings
    with self.settings_path.open("r", encoding="utf-8") as f:
  File "/usr/local/Cellar/python@3.10/3.10.1/Frameworks/Python.framework/Versions/3.10/lib/python3.10/pathlib.py", line 1117, in open
    return self._accessor.open(self, mode, buffering, encoding, errors,
FileNotFoundError: [Errno 2] No such file or directory: '/Volumes/workplace/NM-CFN/src/AWSCloudFormationResourceProvidersNetworkManager/.rpdk-config'

The above exception was the direct cause of the following exception:

Traceback (most recent call last):
  File "/usr/local/Cellar/cloudformation-cli/0.2.22/libexec/lib/python3.10/site-packages/rpdk/core/cli.py", line 100, in main
    args.command(args)
  File "/usr/local/Cellar/cloudformation-cli/0.2.22/libexec/lib/python3.10/site-packages/rpdk/core/validate.py", line 14, in validate
    project.load()
  File "/usr/local/Cellar/cloudformation-cli/0.2.22/libexec/lib/python3.10/site-packages/rpdk/core/project.py", line 444, in load
    self._raise_invalid_project(
  File "/usr/local/Cellar/cloudformation-cli/0.2.22/libexec/lib/python3.10/site-packages/rpdk/core/project.py", line 190, in _raise_invalid_project
    raise InvalidProjectError(msg) from e
rpdk.core.exceptions.InvalidProjectError: Project file /Volumes/workplace/NM-CFN/src/AWSCloudFormationResourceProvidersNetworkManager/.rpdk-config not found. Have you run 'init' or in a wrong directory?
[2022-01-11T06:39:33Z] CRITICAL - Project file /Volumes/workplace/NM-CFN/src/AWSCloudFormationResourceProvidersNetworkManager/.rpdk-config not found. Have you run 'init' or in a wrong directory?
[2022-05-21T19:15:35Z] DEBUG    - Logging set up successfully
[2022-05-21T19:15:35Z] DEBUG    - Running validate: Namespace(version=False, subparser_name='validate', command=<function validate at 0x118a5f490>, verbose=0)
[2022-05-21T19:15:35Z] DEBUG    - Root directory: /Volumes/workplace/NetworkManagerCFN/src/AWSCloudFormationResourceProvidersNetworkManager
[2022-05-21T19:15:35Z] DEBUG    - Loading project file '/Volumes/workplace/NetworkManagerCFN/src/AWSCloudFormationResourceProvidersNetworkManager/.rpdk-config'
[2022-05-21T19:15:35Z] DEBUG    - Project file /Volumes/workplace/NetworkManagerCFN/src/AWSCloudFormationResourceProvidersNetworkManager/.rpdk-config not found. Have you run 'init' or in a wrong directory?
Traceback (most recent call last):
  File "/usr/local/Cellar/cloudformation-cli/0.2.25/libexec/lib/python3.10/site-packages/rpdk/core/project.py", line 562, in load
    self.load_settings()
  File "/usr/local/Cellar/cloudformation-cli/0.2.25/libexec/lib/python3.10/site-packages/rpdk/core/project.py", line 234, in load_settings
    with self.settings_path.open("r", encoding="utf-8") as f:
  File "/usr/local/Cellar/python@3.10/3.10.4/Frameworks/Python.framework/Versions/3.10/lib/python3.10/pathlib.py", line 1117, in open
    return self._accessor.open(self, mode, buffering, encoding, errors,
FileNotFoundError: [Errno 2] No such file or directory: '/Volumes/workplace/NetworkManagerCFN/src/AWSCloudFormationResourceProvidersNetworkManager/.rpdk-config'
[2022-05-21T19:15:35Z] DEBUG    - Caught exit recommendation
Traceback (most recent call last):
  File "/usr/local/Cellar/cloudformation-cli/0.2.25/libexec/lib/python3.10/site-packages/rpdk/core/project.py", line 562, in load
    self.load_settings()
  File "/usr/local/Cellar/cloudformation-cli/0.2.25/libexec/lib/python3.10/site-packages/rpdk/core/project.py", line 234, in load_settings
    with self.settings_path.open("r", encoding="utf-8") as f:
  File "/usr/local/Cellar/python@3.10/3.10.4/Frameworks/Python.framework/Versions/3.10/lib/python3.10/pathlib.py", line 1117, in open
    return self._accessor.open(self, mode, buffering, encoding, errors,
FileNotFoundError: [Errno 2] No such file or directory: '/Volumes/workplace/NetworkManagerCFN/src/AWSCloudFormationResourceProvidersNetworkManager/.rpdk-config'

The above exception was the direct cause of the following exception:

Traceback (most recent call last):
  File "/usr/local/Cellar/cloudformation-cli/0.2.25/libexec/lib/python3.10/site-packages/rpdk/core/cli.py", line 100, in main
    args.command(args)
  File "/usr/local/Cellar/cloudformation-cli/0.2.25/libexec/lib/python3.10/site-packages/rpdk/core/validate.py", line 14, in validate
    project.load()
  File "/usr/local/Cellar/cloudformation-cli/0.2.25/libexec/lib/python3.10/site-packages/rpdk/core/project.py", line 564, in load
    self._raise_invalid_project(
  File "/usr/local/Cellar/cloudformation-cli/0.2.25/libexec/lib/python3.10/site-packages/rpdk/core/project.py", line 229, in _raise_invalid_project
    raise InvalidProjectError(msg) from e
rpdk.core.exceptions.InvalidProjectError: Project file /Volumes/workplace/NetworkManagerCFN/src/AWSCloudFormationResourceProvidersNetworkManager/.rpdk-config not found. Have you run 'init' or in a wrong directory?
[2022-05-21T19:15:35Z] CRITICAL - Project file /Volumes/workplace/NetworkManagerCFN/src/AWSCloudFormationResourceProvidersNetworkManager/.rpdk-config not found. Have you run 'init' or in a wrong directory?
[2022-06-29T03:53:50Z] DEBUG    - Logging set up successfully
[2022-06-29T03:53:50Z] DEBUG    - Running test: Namespace(version=False, subparser_name='test', command=<function test at 0x121149280>, verbose=0, endpoint='http://127.0.0.1:3001', function_name='TypeFunction', region='us-east-1', role_arn=None, cloudformation_endpoint_url=None, enforce_timeout='30', log_group_name=None, log_role_arn=None, passed_to_pytest=['-k', 'contract_update_read'], docker_image=None)
[2022-06-29T03:53:50Z] DEBUG    - Root directory: /Volumes/workplace/NM-NewResource/src/AWSCloudFormationResourceProvidersNetworkManager
[2022-06-29T03:53:50Z] DEBUG    - Loading project file '/Volumes/workplace/NM-NewResource/src/AWSCloudFormationResourceProvidersNetworkManager/.rpdk-config'
[2022-06-29T03:53:50Z] DEBUG    - Project file /Volumes/workplace/NM-NewResource/src/AWSCloudFormationResourceProvidersNetworkManager/.rpdk-config not found. Have you run 'init' or in a wrong directory?
Traceback (most recent call last):
  File "/usr/local/lib/python3.9/site-packages/rpdk/core/project.py", line 562, in load
    self.load_settings()
  File "/usr/local/lib/python3.9/site-packages/rpdk/core/project.py", line 234, in load_settings
    with self.settings_path.open("r", encoding="utf-8") as f:
  File "/usr/local/Cellar/python@3.9/3.9.12/Frameworks/Python.framework/Versions/3.9/lib/python3.9/pathlib.py", line 1252, in open
    return io.open(self, mode, buffering, encoding, errors, newline,
  File "/usr/local/Cellar/python@3.9/3.9.12/Frameworks/Python.framework/Versions/3.9/lib/python3.9/pathlib.py", line 1120, in _opener
    return self._accessor.open(self, flags, mode)
FileNotFoundError: [Errno 2] No such file or directory: '/Volumes/workplace/NM-NewResource/src/AWSCloudFormationResourceProvidersNetworkManager/.rpdk-config'
[2022-06-29T03:53:50Z] DEBUG    - Caught exit recommendation
Traceback (most recent call last):
  File "/usr/local/lib/python3.9/site-packages/rpdk/core/project.py", line 562, in load
    self.load_settings()
  File "/usr/local/lib/python3.9/site-packages/rpdk/core/project.py", line 234, in load_settings
    with self.settings_path.open("r", encoding="utf-8") as f:
  File "/usr/local/Cellar/python@3.9/3.9.12/Frameworks/Python.framework/Versions/3.9/lib/python3.9/pathlib.py", line 1252, in open
    return io.open(self, mode, buffering, encoding, errors, newline,
  File "/usr/local/Cellar/python@3.9/3.9.12/Frameworks/Python.framework/Versions/3.9/lib/python3.9/pathlib.py", line 1120, in _opener
    return self._accessor.open(self, flags, mode)
FileNotFoundError: [Errno 2] No such file or directory: '/Volumes/workplace/NM-NewResource/src/AWSCloudFormationResourceProvidersNetworkManager/.rpdk-config'

The above exception was the direct cause of the following exception:

Traceback (most recent call last):
  File "/usr/local/lib/python3.9/site-packages/rpdk/core/cli.py", line 100, in main
    args.command(args)
  File "/usr/local/lib/python3.9/site-packages/rpdk/core/test.py", line 354, in test
    project.load()
  File "/usr/local/lib/python3.9/site-packages/rpdk/core/project.py", line 564, in load
    self._raise_invalid_project(
  File "/usr/local/lib/python3.9/site-packages/rpdk/core/project.py", line 229, in _raise_invalid_project
    raise InvalidProjectError(msg) from e
rpdk.core.exceptions.InvalidProjectError: Project file /Volumes/workplace/NM-NewResource/src/AWSCloudFormationResourceProvidersNetworkManager/.rpdk-config not found. Have you run 'init' or in a wrong directory?
[2022-06-29T03:53:50Z] CRITICAL - Project file /Volumes/workplace/NM-NewResource/src/AWSCloudFormationResourceProvidersNetworkManager/.rpdk-config not found. Have you run 'init' or in a wrong directory?
[2022-08-08T05:39:52Z] DEBUG    - Logging set up successfully
[2022-08-08T05:39:52Z] DEBUG    - Running validate: Namespace(version=False, subparser_name='validate', command=<function validate at 0x1189e1b80>, verbose=0)
[2022-08-08T05:39:52Z] DEBUG    - Root directory: /Volumes/workplace/NetworkManagerCFN/src/AWSCloudFormationResourceProvidersNetworkManager
[2022-08-08T05:39:52Z] DEBUG    - Loading project file '/Volumes/workplace/NetworkManagerCFN/src/AWSCloudFormationResourceProvidersNetworkManager/.rpdk-config'
[2022-08-08T05:39:52Z] DEBUG    - Project file /Volumes/workplace/NetworkManagerCFN/src/AWSCloudFormationResourceProvidersNetworkManager/.rpdk-config not found. Have you run 'init' or in a wrong directory?
Traceback (most recent call last):
  File "/usr/local/lib/python3.9/site-packages/rpdk/core/project.py", line 562, in load
    self.load_settings()
  File "/usr/local/lib/python3.9/site-packages/rpdk/core/project.py", line 234, in load_settings
    with self.settings_path.open("r", encoding="utf-8") as f:
  File "/usr/local/Cellar/python@3.9/3.9.12/Frameworks/Python.framework/Versions/3.9/lib/python3.9/pathlib.py", line 1252, in open
    return io.open(self, mode, buffering, encoding, errors, newline,
  File "/usr/local/Cellar/python@3.9/3.9.12/Frameworks/Python.framework/Versions/3.9/lib/python3.9/pathlib.py", line 1120, in _opener
    return self._accessor.open(self, flags, mode)
FileNotFoundError: [Errno 2] No such file or directory: '/Volumes/workplace/NetworkManagerCFN/src/AWSCloudFormationResourceProvidersNetworkManager/.rpdk-config'
[2022-08-08T05:39:52Z] DEBUG    - Caught exit recommendation
Traceback (most recent call last):
  File "/usr/local/lib/python3.9/site-packages/rpdk/core/project.py", line 562, in load
    self.load_settings()
  File "/usr/local/lib/python3.9/site-packages/rpdk/core/project.py", line 234, in load_settings
    with self.settings_path.open("r", encoding="utf-8") as f:
  File "/usr/local/Cellar/python@3.9/3.9.12/Frameworks/Python.framework/Versions/3.9/lib/python3.9/pathlib.py", line 1252, in open
    return io.open(self, mode, buffering, encoding, errors, newline,
  File "/usr/local/Cellar/python@3.9/3.9.12/Frameworks/Python.framework/Versions/3.9/lib/python3.9/pathlib.py", line 1120, in _opener
    return self._accessor.open(self, flags, mode)
FileNotFoundError: [Errno 2] No such file or directory: '/Volumes/workplace/NetworkManagerCFN/src/AWSCloudFormationResourceProvidersNetworkManager/.rpdk-config'

The above exception was the direct cause of the following exception:

Traceback (most recent call last):
  File "/usr/local/lib/python3.9/site-packages/rpdk/core/cli.py", line 100, in main
    args.command(args)
  File "/usr/local/lib/python3.9/site-packages/rpdk/core/validate.py", line 14, in validate
    project.load()
  File "/usr/local/lib/python3.9/site-packages/rpdk/core/project.py", line 564, in load
    self._raise_invalid_project(
  File "/usr/local/lib/python3.9/site-packages/rpdk/core/project.py", line 229, in _raise_invalid_project
    raise InvalidProjectError(msg) from e
rpdk.core.exceptions.InvalidProjectError: Project file /Volumes/workplace/NetworkManagerCFN/src/AWSCloudFormationResourceProvidersNetworkManager/.rpdk-config not found. Have you run 'init' or in a wrong directory?
[2022-08-08T05:39:52Z] CRITICAL - Project file /Volumes/workplace/NetworkManagerCFN/src/AWSCloudFormationResourceProvidersNetworkManager/.rpdk-config not found. Have you run 'init' or in a wrong directory?
[2022-08-09T21:03:16Z] DEBUG    - Logging set up successfully
[2022-08-09T21:03:16Z] DEBUG    - Running test: Namespace(version=False, subparser_name='test', command=<function test at 0x11a6f6280>, verbose=0, endpoint='http://127.0.0.1:3001', function_name='TypeFunction', region='us-east-1', role_arn=None, cloudformation_endpoint_url=None, enforce_timeout='30', log_group_name=None, log_role_arn=None, passed_to_pytest=['-k', 'contract_create_delete'], docker_image=None)
[2022-08-09T21:03:16Z] DEBUG    - Root directory: /Volumes/workplace/NetworkManagerCFN/src/AWSCloudFormationResourceProvidersNetworkManager
[2022-08-09T21:03:16Z] DEBUG    - Loading project file '/Volumes/workplace/NetworkManagerCFN/src/AWSCloudFormationResourceProvidersNetworkManager/.rpdk-config'
[2022-08-09T21:03:16Z] DEBUG    - Project file /Volumes/workplace/NetworkManagerCFN/src/AWSCloudFormationResourceProvidersNetworkManager/.rpdk-config not found. Have you run 'init' or in a wrong directory?
Traceback (most recent call last):
  File "/usr/local/lib/python3.9/site-packages/rpdk/core/project.py", line 562, in load
    self.load_settings()
  File "/usr/local/lib/python3.9/site-packages/rpdk/core/project.py", line 234, in load_settings
    with self.settings_path.open("r", encoding="utf-8") as f:
  File "/usr/local/Cellar/python@3.9/3.9.12/Frameworks/Python.framework/Versions/3.9/lib/python3.9/pathlib.py", line 1252, in open
    return io.open(self, mode, buffering, encoding, errors, newline,
  File "/usr/local/Cellar/python@3.9/3.9.12/Frameworks/Python.framework/Versions/3.9/lib/python3.9/pathlib.py", line 1120, in _opener
    return self._accessor.open(self, flags, mode)
FileNotFoundError: [Errno 2] No such file or directory: '/Volumes/workplace/NetworkManagerCFN/src/AWSCloudFormationResourceProvidersNetworkManager/.rpdk-config'
[2022-08-09T21:03:16Z] DEBUG    - Caught exit recommendation
Traceback (most recent call last):
  File "/usr/local/lib/python3.9/site-packages/rpdk/core/project.py", line 562, in load
    self.load_settings()
  File "/usr/local/lib/python3.9/site-packages/rpdk/core/project.py", line 234, in load_settings
    with self.settings_path.open("r", encoding="utf-8") as f:
  File "/usr/local/Cellar/python@3.9/3.9.12/Frameworks/Python.framework/Versions/3.9/lib/python3.9/pathlib.py", line 1252, in open
    return io.open(self, mode, buffering, encoding, errors, newline,
  File "/usr/local/Cellar/python@3.9/3.9.12/Frameworks/Python.framework/Versions/3.9/lib/python3.9/pathlib.py", line 1120, in _opener
    return self._accessor.open(self, flags, mode)
FileNotFoundError: [Errno 2] No such file or directory: '/Volumes/workplace/NetworkManagerCFN/src/AWSCloudFormationResourceProvidersNetworkManager/.rpdk-config'

The above exception was the direct cause of the following exception:

Traceback (most recent call last):
  File "/usr/local/lib/python3.9/site-packages/rpdk/core/cli.py", line 100, in main
    args.command(args)
  File "/usr/local/lib/python3.9/site-packages/rpdk/core/test.py", line 354, in test
    project.load()
  File "/usr/local/lib/python3.9/site-packages/rpdk/core/project.py", line 564, in load
    self._raise_invalid_project(
  File "/usr/local/lib/python3.9/site-packages/rpdk/core/project.py", line 229, in _raise_invalid_project
    raise InvalidProjectError(msg) from e
rpdk.core.exceptions.InvalidProjectError: Project file /Volumes/workplace/NetworkManagerCFN/src/AWSCloudFormationResourceProvidersNetworkManager/.rpdk-config not found. Have you run 'init' or in a wrong directory?
[2022-08-09T21:03:16Z] CRITICAL - Project file /Volumes/workplace/NetworkManagerCFN/src/AWSCloudFormationResourceProvidersNetworkManager/.rpdk-config not found. Have you run 'init' or in a wrong directory?
[2022-11-02T02:19:47Z] DEBUG    - Logging set up successfully
[2022-11-02T02:19:47Z] DEBUG    - Running test: Namespace(version=False, subparser_name='test', command=<function test at 0x11a61d430>, verbose=0, endpoint='http://127.0.0.1:3001', function_name='TypeFunction', region='us-east-1', role_arn=None, cloudformation_endpoint_url=None, enforce_timeout='30', log_group_name=None, log_role_arn=None, passed_to_pytest=[], docker_image=None)
[2022-11-02T02:19:47Z] DEBUG    - Root directory: /Users/mashehat/Documents/AWSCloudFormationResourceProvidersNetworkManager/src/AWSCloudFormationResourceProvidersNetworkManager
[2022-11-02T02:19:47Z] DEBUG    - Loading project file '/Users/mashehat/Documents/AWSCloudFormationResourceProvidersNetworkManager/src/AWSCloudFormationResourceProvidersNetworkManager/.rpdk-config'
[2022-11-02T02:19:47Z] DEBUG    - Project file /Users/mashehat/Documents/AWSCloudFormationResourceProvidersNetworkManager/src/AWSCloudFormationResourceProvidersNetworkManager/.rpdk-config not found. Have you run 'init' or in a wrong directory?
Traceback (most recent call last):
  File "/usr/local/lib/python3.9/site-packages/rpdk/core/project.py", line 562, in load
    self.load_settings()
  File "/usr/local/lib/python3.9/site-packages/rpdk/core/project.py", line 234, in load_settings
    with self.settings_path.open("r", encoding="utf-8") as f:
  File "/usr/local/Cellar/python@3.9/3.9.13_1/Frameworks/Python.framework/Versions/3.9/lib/python3.9/pathlib.py", line 1252, in open
    return io.open(self, mode, buffering, encoding, errors, newline,
  File "/usr/local/Cellar/python@3.9/3.9.13_1/Frameworks/Python.framework/Versions/3.9/lib/python3.9/pathlib.py", line 1120, in _opener
    return self._accessor.open(self, flags, mode)
FileNotFoundError: [Errno 2] No such file or directory: '/Users/mashehat/Documents/AWSCloudFormationResourceProvidersNetworkManager/src/AWSCloudFormationResourceProvidersNetworkManager/.rpdk-config'
[2022-11-02T02:19:47Z] DEBUG    - Caught exit recommendation
Traceback (most recent call last):
  File "/usr/local/lib/python3.9/site-packages/rpdk/core/project.py", line 562, in load
    self.load_settings()
  File "/usr/local/lib/python3.9/site-packages/rpdk/core/project.py", line 234, in load_settings
    with self.settings_path.open("r", encoding="utf-8") as f:
  File "/usr/local/Cellar/python@3.9/3.9.13_1/Frameworks/Python.framework/Versions/3.9/lib/python3.9/pathlib.py", line 1252, in open
    return io.open(self, mode, buffering, encoding, errors, newline,
  File "/usr/local/Cellar/python@3.9/3.9.13_1/Frameworks/Python.framework/Versions/3.9/lib/python3.9/pathlib.py", line 1120, in _opener
    return self._accessor.open(self, flags, mode)
FileNotFoundError: [Errno 2] No such file or directory: '/Users/mashehat/Documents/AWSCloudFormationResourceProvidersNetworkManager/src/AWSCloudFormationResourceProvidersNetworkManager/.rpdk-config'

The above exception was the direct cause of the following exception:

Traceback (most recent call last):
  File "/usr/local/lib/python3.9/site-packages/rpdk/core/cli.py", line 100, in main
    args.command(args)
  File "/usr/local/lib/python3.9/site-packages/rpdk/core/test.py", line 354, in test
    project.load()
  File "/usr/local/lib/python3.9/site-packages/rpdk/core/project.py", line 564, in load
    self._raise_invalid_project(
  File "/usr/local/lib/python3.9/site-packages/rpdk/core/project.py", line 229, in _raise_invalid_project
    raise InvalidProjectError(msg) from e
rpdk.core.exceptions.InvalidProjectError: Project file /Users/mashehat/Documents/AWSCloudFormationResourceProvidersNetworkManager/src/AWSCloudFormationResourceProvidersNetworkManager/.rpdk-config not found. Have you run 'init' or in a wrong directory?
[2022-11-02T02:19:47Z] CRITICAL - Project file /Users/mashehat/Documents/AWSCloudFormationResourceProvidersNetworkManager/src/AWSCloudFormationResourceProvidersNetworkManager/.rpdk-config not found. Have you run 'init' or in a wrong directory?
[2022-11-02T02:20:12Z] DEBUG    - Logging set up successfully
[2022-11-02T02:20:12Z] DEBUG    - Running None: Namespace(version=False, subparser_name=None, command=<function init at 0x1181ea280>, verbose=0, force=False, type_name=None, artifact_type=None, endpoint_url=None, region=None, target_schemas=[])
[2022-11-02T02:20:12Z] DEBUG    - Root directory: /Users/mashehat/Documents/AWSCloudFormationResourceProvidersNetworkManager/src/AWSCloudFormationResourceProvidersNetworkManager
[2022-11-02T02:20:12Z] WARNING  - Initializing new project
[2022-11-02T02:20:12Z] DEBUG    - Loading project file '/Users/mashehat/Documents/AWSCloudFormationResourceProvidersNetworkManager/src/AWSCloudFormationResourceProvidersNetworkManager/.rpdk-config'
[2022-11-02T02:23:53Z] DEBUG    - Logging set up successfully
[2022-11-02T02:23:53Z] DEBUG    - Running test: Namespace(version=False, subparser_name='test', command=<function test at 0x121dbd550>, verbose=0, endpoint='http://127.0.0.1:3001', function_name='TypeFunction', region='us-east-1', role_arn=None, cloudformation_endpoint_url=None, enforce_timeout='30', log_group_name=None, log_role_arn=None, passed_to_pytest=[], docker_image=None)
[2022-11-02T02:23:53Z] DEBUG    - Root directory: /Users/mashehat/Documents/AWSCloudFormationResourceProvidersNetworkManager/src/AWSCloudFormationResourceProvidersNetworkManager
[2022-11-02T02:23:53Z] DEBUG    - Loading project file '/Users/mashehat/Documents/AWSCloudFormationResourceProvidersNetworkManager/src/AWSCloudFormationResourceProvidersNetworkManager/.rpdk-config'
[2022-11-02T02:23:53Z] DEBUG    - Project file /Users/mashehat/Documents/AWSCloudFormationResourceProvidersNetworkManager/src/AWSCloudFormationResourceProvidersNetworkManager/.rpdk-config not found. Have you run 'init' or in a wrong directory?
Traceback (most recent call last):
  File "/usr/local/lib/python3.9/site-packages/rpdk/core/project.py", line 562, in load
    self.load_settings()
  File "/usr/local/lib/python3.9/site-packages/rpdk/core/project.py", line 234, in load_settings
    with self.settings_path.open("r", encoding="utf-8") as f:
  File "/usr/local/Cellar/python@3.9/3.9.13_1/Frameworks/Python.framework/Versions/3.9/lib/python3.9/pathlib.py", line 1252, in open
    return io.open(self, mode, buffering, encoding, errors, newline,
  File "/usr/local/Cellar/python@3.9/3.9.13_1/Frameworks/Python.framework/Versions/3.9/lib/python3.9/pathlib.py", line 1120, in _opener
    return self._accessor.open(self, flags, mode)
FileNotFoundError: [Errno 2] No such file or directory: '/Users/mashehat/Documents/AWSCloudFormationResourceProvidersNetworkManager/src/AWSCloudFormationResourceProvidersNetworkManager/.rpdk-config'
[2022-11-02T02:23:53Z] DEBUG    - Caught exit recommendation
Traceback (most recent call last):
  File "/usr/local/lib/python3.9/site-packages/rpdk/core/project.py", line 562, in load
    self.load_settings()
  File "/usr/local/lib/python3.9/site-packages/rpdk/core/project.py", line 234, in load_settings
    with self.settings_path.open("r", encoding="utf-8") as f:
  File "/usr/local/Cellar/python@3.9/3.9.13_1/Frameworks/Python.framework/Versions/3.9/lib/python3.9/pathlib.py", line 1252, in open
    return io.open(self, mode, buffering, encoding, errors, newline,
  File "/usr/local/Cellar/python@3.9/3.9.13_1/Frameworks/Python.framework/Versions/3.9/lib/python3.9/pathlib.py", line 1120, in _opener
    return self._accessor.open(self, flags, mode)
FileNotFoundError: [Errno 2] No such file or directory: '/Users/mashehat/Documents/AWSCloudFormationResourceProvidersNetworkManager/src/AWSCloudFormationResourceProvidersNetworkManager/.rpdk-config'

The above exception was the direct cause of the following exception:

Traceback (most recent call last):
  File "/usr/local/lib/python3.9/site-packages/rpdk/core/cli.py", line 100, in main
    args.command(args)
  File "/usr/local/lib/python3.9/site-packages/rpdk/core/test.py", line 354, in test
    project.load()
  File "/usr/local/lib/python3.9/site-packages/rpdk/core/project.py", line 564, in load
    self._raise_invalid_project(
  File "/usr/local/lib/python3.9/site-packages/rpdk/core/project.py", line 229, in _raise_invalid_project
    raise InvalidProjectError(msg) from e
rpdk.core.exceptions.InvalidProjectError: Project file /Users/mashehat/Documents/AWSCloudFormationResourceProvidersNetworkManager/src/AWSCloudFormationResourceProvidersNetworkManager/.rpdk-config not found. Have you run 'init' or in a wrong directory?
[2022-11-02T02:23:53Z] CRITICAL - Project file /Users/mashehat/Documents/AWSCloudFormationResourceProvidersNetworkManager/src/AWSCloudFormationResourceProvidersNetworkManager/.rpdk-config not found. Have you run 'init' or in a wrong directory?
